# 13

## 13.1

1.

```rust
fn drink(beverage: &str) {
    if beverage == "lemonade" {
        println!("Success!");
        // 实现下面的代码
        panic!("sd");
    }

    println!("Exercise Failed if printing out this line!");
}

fn main() {
    drink("lemonade");

    println!("Exercise Failed if printing out this line!");
}
```

2.

```rust
// 修复所有的 panic，让代码工作
fn main() {
    assert_eq!("abc".as_bytes(), [97, 98, 99]);

    let v = vec![1, 2, 3];
    let ele = v[2];
    let ele = v.get(2).unwrap();

    // 大部分时候编译器是可以帮我们提前发现溢出错误，并阻止编译通过。但是也有一些时候，这种溢出问题直到运行期才会出现
    let v = production_rate_per_hour(2);

    divide(15, 1);

    println!("Success!")
}

fn divide(x: u8, y: u8) {
    println!("{}", x / y)
}

fn production_rate_per_hour(speed: u8) -> f64 {
    let cph: u8 = 221;
    match speed {
        1..=4 => (speed * cph) as f64,
        5..=8 => (speed * cph) as f64 * 0.9,
        9..=10 => (speed * cph) as f64 * 0.77,
        _ => 0 as f64,
    }
}

pub fn working_items_per_minute(speed: u8) -> u32 {
    (production_rate_per_hour(speed) / 60 as f64) as u32
}
```

3.

```sh
$ RUST_BACKTRACE=1 cargo run
thread 'main' panicked at 'assertion failed: `(left == right)`
  left: `[97, 98, 99]`,
 right: `[96, 97, 98]`', src/main.rs:3:5
stack backtrace:
   0: rust_begin_unwind
             at /rustc/9d1b2106e23b1abd32fce1f17267604a5102f57a/library/std/src/panicking.rs:498:5
   1: core::panicking::panic_fmt
             at /rustc/9d1b2106e23b1abd32fce1f17267604a5102f57a/library/core/src/panicking.rs:116:14
   2: core::panicking::assert_failed_inner
   3: core::panicking::assert_failed
             at /rustc/9d1b2106e23b1abd32fce1f17267604a5102f57a/library/core/src/panicking.rs:154:5
   4: study_cargo::main
             at ./src/main.rs:3:5
   5: core::ops::function::FnOnce::call_once
             at /rustc/9d1b2106e23b1abd32fce1f17267604a5102f57a/library/core/src/ops/function.rs:227:5
note: Some details are omitted, run with `RUST_BACKTRACE=full` for a verbose backtrace.
```

---

## 13.2

1.

```rust
// 填空并修复错误
use std::num::ParseIntError;

fn multiply(n1_str: &str, n2_str: &str) -> Result<i32, ParseIntError> {
    let n1 = n1_str.parse::<i32>();
    let n2 = n2_str.parse::<i32>();
    Ok(n1.unwrap() * n2.unwrap())
}

fn main() {
    let result = multiply("10", "2");
    assert_eq!(result, Ok(20));

    let result = multiply("4", "2");
    assert_eq!(result, Ok(8));

    println!("Success!")
}
```

2.

```rust
use std::num::ParseIntError;

// 使用 `?` 来实现 multiply
// 不要使用 unwrap !
fn multiply(n1_str: &str, n2_str: &str) -> Result<i32, ParseIntError> {
    let x = n1_str.parse::<i32>()?;
    let y = n2_str.parse::<i32>()?;
    Ok(x * y)
}

fn main() {
    assert_eq!(multiply("3", "4").unwrap(), 12);
    println!("Success!")
}
```

3.

```rust
use std::num::ParseIntError;

// 使用两种方式填空: map, and then
fn add_two(n_str: &str) -> Result<i32, ParseIntError> {
    n_str.parse::<i32>().map(|x| x + 2)
}

fn add_two(n_str: &str) -> Result<i32, ParseIntError> {
    n_str.parse::<i32>().and_then(|x| Ok(x + 2))
}
fn main() {
    assert_eq!(add_two("4").unwrap(), 6);

    println!("Success!")
}
```

4.

```rust
use std::num::ParseIntError;

// 使用 Result 重写后，我们使用模式匹配的方式来处理，而无需使用 `unwrap`
// 但是这种写法实在过于啰嗦..
fn multiply(n1_str: &str, n2_str: &str) -> Result<i32, ParseIntError> {
    match n1_str.parse::<i32>() {
        Ok(n1) => match n2_str.parse::<i32>() {
            Ok(n2) => Ok(n1 * n2),
            Err(e) => Err(e),
        },
        Err(e) => Err(e),
    }
}

// 重写上面的 `multiply` ，让它尽量简洁
// 提示：使用 `and_then` 和 `map`
fn multiply1(n1_str: &str, n2_str: &str) -> Result<i32, ParseIntError> {
    n1_str.parse::<i32>().and_then(|x| {
        n2_str.parse::<i32>().map(|y| x * y)
    })
}

fn print(result: Result<i32, ParseIntError>) {
    match result {
        Ok(n) => println!("n is {}", n),
        Err(e) => println!("Error: {}", e),
    }
}

fn main() {
    let twenty = multiply1("10", "2");
    print(twenty);

    // 下面的调用会提供更有帮助的错误信息
    let tt = multiply("t", "2");
    print(tt);

    println!("Success!")
}
```

5.

```rust
use std::num::ParseIntError;

// 使用 Result 重写后，我们使用模式匹配的方式来处理，而无需使用 `unwrap`
// 但是这种写法实在过于啰嗦..
fn multiply(n1_str: &str, n2_str: &str) -> Result<i32, ParseIntError> {
    match n1_str.parse::<i32>() {
        Ok(n1) => match n2_str.parse::<i32>() {
            Ok(n2) => Ok(n1 * n2),
            Err(e) => Err(e),
        },
        Err(e) => Err(e),
    }
}

// 重写上面的 `multiply` ，让它尽量简洁
// 提示：使用 `and_then` 和 `map`
fn multiply1(n1_str: &str, n2_str: &str) -> Result<i32, ParseIntError> {
    n1_str
        .parse::<i32>()
        .and_then(|x| n2_str.parse::<i32>().map(|y| x * y))
}

fn print(result: Result<i32, ParseIntError>) {
    match result {
        Ok(n) => println!("n is {}", n),
        Err(e) => println!("Error: {}", e),
    }
}

fn main() {
    let twenty = multiply1("10", "2");
    print(twenty);

    // 下面的调用会提供更有帮助的错误信息
    let tt = multiply("t", "2");
    print(tt);

    println!("Success!")
}
```

6.

```rust
use std::num::ParseIntError;

// 填空
type Res<T> = Result<T, ParseIntError>;

// 使用上面的别名来引用原来的 `Result` 类型
fn multiply(first_number_str: &str, second_number_str: &str) -> Res<i32> {
    first_number_str.parse::<i32>().and_then(|first_number| {
        second_number_str
            .parse::<i32>()
            .map(|second_number| first_number * second_number)
    })
}

// 同样, 这里也使用了类型别名来简化代码
fn print(result: Res<i32>) {
    match result {
        Ok(n) => println!("n is {}", n),
        Err(e) => println!("ErrorI: {}", e),
    }
}

fn main() {
    print(multiply("10", "2"));
    print(multiply("t", "2"));

    println!("Success!")
}
```
